Workbook

Sheet Salários
A1: Atletas com maiores folhas de pagamento
A2: Atleta | B2: Remuneração em 2014 | C2: Salário/Bolsa/Premiações | D2: Patrocínios | E2: Esporte
A3: Floyd Mayweather | B3: $105 M | C3: $105 M | D3: 0 | E3: Boxing
A4: Cristiano Ronaldo | B4: $80 M | C4: $52 M | D4: $28 M | E4: Soccer
A5: LeBron James | B5: $72.3 M | C5: $19.3 M | D5: $53 M | E5: Basketball
A6: Lionel Messi | B6: $64.7 M | C6: $41.7 M | D6: $23 M | E6: Soccer
A7: Kobe Bryant | B7: $61.5 M | C7: $30.5 M | D7: $31 M | E7: Basketball
A8: Tiger Woods | B8: $61.2 M | C8: $6.2 M | D8: $55 M | E8: Golf
A9: Roger Federer | B9: $56.2 M | C9: $4.2 M | D9: $52 M | E9: Tennis
A10: Phil Mickelson | B10: $53.2 M | C10: $5.2 M | D10: $48 M | E10: Golf
A11: Rafael Nadal | B11: $44.5 M | C11: $14.5 M | D11: $30 M | E11: Tennis
A12: Matt Ryan | B12: $43.8 M | C12: $42 M | D12: $1.8 M | E12: Football
A13: Manny Pacquiao | B13: $41.8 M | C13: $41 M | D13: $0.8 M | E13: Boxing
A14: Zlatan Ibrahimovic | B14: $40.4 M | C14: $36.4 M | D14: $4 M | E14: Soccer
A15: Derrick Rose | B15: $36.6 M | C15: $17.6 M | D15: $19 M | E15: Basketball
... A102: Luis Suarez | B102: $17.3 M | C102: $13.3 M | D102: $4 M | E102: Soccer

Sheet Analises
A1: Quantidade de aparições no ranking
A2: EPL | B2: =COUNTIF(Folhas_de_pagamento!C2:C232,"*EPL*") -> 0
A3: MLB | B3: =COUNTIF(Folhas_de_pagamento!D3:D233,Analises!A3) -> 0
A4: La liga | B4: =COUNTIF(Folhas_de_pagamento!D4:D234,Analises!A4) -> 0
A5: NBA | B5: =COUNTIF(Folhas_de_pagamento!D5:D235,Analises!A5) -> 0
A6: Bundesliga | B6: =COUNTIF(Folhas_de_pagamento!D6:D236,Analises!A6) -> 0
A7: Serie A | B7: =COUNTIF(Folhas_de_pagamento!D7:D237,Analises!A7) -> 0
A8: IPL | B8: =COUNTIF(Folhas_de_pagamento!D8:D238,Analises!A8) -> 0
A9: NHL | B9: =COUNTIF(Folhas_de_pagamento!D9:D239,Analises!A9) -> 0
A10: CSL | B10: =COUNTIF(Folhas_de_pagamento!D10:D240,Analises!A10) -> 0
A11: NPB | B11: =COUNTIF(Folhas_de_pagamento!D11:D241,Analises!A11) -> 0
A12: SPL | B12: =COUNTIF(Folhas_de_pagamento!D12:D242,Analises!A12) -> 0
A13: MLS | B13: =COUNTIF(Folhas_de_pagamento!D13:D243,Analises!A13) -> 0
A14: AFL | B14: =COUNTIF(Folhas_de_pagamento!D14:D244,Analises!A14) -> 0
A15: NPB | B15: =COUNTIF(Folhas_de_pagamento!D15:D245,Analises!A15) -> 0

Sheet Folhas_de_pagamento
A1: Ranking de times com maiores folhas de pagamento
A2: Ranking | B2: Ranking no último ano | C2: Time | D2: Liga | E2: Salário médio atual por jogador | F2: %Variação em relação ao ano anterior | G2: Folha salarial | H2: Ranking de folha salarial | I2: Ganho médio do jogador em 5 anos | J2: % Variação dos últimos 5 anos
A3: 1 | B3: 1 | C3: Manchester City | D3: EPL | E3: 8109912 | F3: 0.6 | G3: 202747812 | H3: 3 | I3: 31660772 | J3: 265 | L3: Quantidade de aparições no ranking
A4: 2 | B4: 5 | C4: New York Yankees | D4: MLB | E4: 8031948 | F4: 12.3 | G4: 208830659 | H4: 2 | I4: 35789052 | J4: 5 | L4: EPL | M4: =COUNTIF(D3:D294,D3=L4) -> 0
A5: 3 | B5: 2 | C5: Los Angeles Dodgers | D5: MLB | E5: 7778336 | F5: 4.1 | G5: 241128402 | H5: 1 | I5: 26226200 | J5: 79 | L5: MLB | M5: =COUNTIF(D4:D295,D4=L5) -> 0
A6: 4 | B6: 3 | C6: Real Madrid | D6: La Liga | E6: 7586438 | F6: 3.7 | G6: 189660944 | H6: 5 | I6: 36995660 | J6: 9 | L6: La liga | M6: =COUNTIF(D5:D296,D5=L6) -> 0
A7: 5 | B7: 4 | C7: Barcelona | D7: La Liga | E7: 7446562 | F7: 2.4 | G7: 193610600 | H7: 4 | I7: 37975600 | J7: 12 | L7: NBA | M7: =COUNTIF(D6:D297,D6=L7) -> 0
A8: 6 | B8: 16 | C8: Brooklyn Nets | D8: NBA | E8: 6814067 | F8: 23.6 | G8: 102211009 | H8: 51 | I8: 24108812 | J8: 65 | L8: Bundesliga | M8: =COUNTIF(D7:D298,D7=L8) -> 0
A9: 7 | B9: 9 | C9: Bayern Munich | D9: Bundesliga | E9: 6689311 | F9: 8.7 | G9: 173922091 | H9: 7 | I9: 29919552 | J9: 36 | L9: Serie A | M9: =COUNTIF(D8:D299,D8=L9) -> 0
A10: 8 | B10: 12 | C10: Manchester United | D10: EPL | E10: 6566775 | F10: 8.9 | G10: 164169367 | H10: 8 | I10: 27985256 | J10: 38 | L10: IPL | M10: =COUNTIF(D9:D300,D9=L10) -> 0
A11: 9 | B11: 19 | C11: Chicago Bulls | D11: NBA | E11: 6055463 | F11: 14.5 | G11: 78721016 | H11: 76 | I11: 24709880 | J11: 51 | L11: NHL | M11: =COUNTIF(D10:D301,D10=L11) -> 0
A12: 10 | B12: 8 | C12: Chelsea | D12: EPL | E12: 6053686 | F12: -3 | G12: 151342140 | H12: 12 | I12: 30990544 | J12: 3 | L12: CSL | M12: =COUNTIF(D11:D302,D11=L12) -> 0
A13: 11 | B13: 15 | C13: Arsenal | D13: EPL | E13: 5928172 | F13: 5.1 | G13: 148204312 | H13: 15 | I13: 25892620 | J13: 38 | L13: NPB | M13: =COUNTIF(D12:D303,D12=L13) -> 0
A14: 12 | B14: 20 | C14: NY Knicks | D14: NBA | E14: 5867808 | F14: 13.5 | G14: 88017120 | H14: 67 | I14: 24425648 | J14: 10 | L14: SPL | M14: =COUNTIF(D13:D304,D13=L14) -> 0
A15: 13 | B15: 14 | C15: Detroit Tigers | D15: MLB | E15: 5824233 | F15: 2 | G15: 163078526 | H15: 9 | I15: 24444264 | J15: 31 | L15: MLS | M15: =COUNTIF(D14:D305,D14=L15) -> 0
A16: 14 | B16: 11 | C16: Philadelphia Phillies | D16: MLB | E16: 5791002 | F16: -5.5 | G16: 179521056 | H16: 6 | I16: 27555684 | J16: 43 | L16: AFL | M16: =COUNTIF(D15:D306,D15=L16) -> 0
A17: 15 | B17: 22 | C17: Boston Red Sox | D17: MLB | E17: 5717792 | F17: 13.9 | G17: 154380395 | H17: 11 | I17: 26406068 | J17: 25
A18: 16 | B18: 17 | C18: Miami Heat | D18: NBA | E18: 5568543 | F18: 1.3 | G18: 83528143 | H18: 72 | I18: 23380396 | J18: 54
A19: 17 | B19: 23 | C19: San Francisco Giants | D19: MLB | E19: 5490339 | F19: 9.6 | G19: 148239158 | H19: 14 | I19: 21697572 | J19: 89
A20: 18 | B20: 35 | C20: Juventus | D20: Serie A | E20: 5336821 | F20: 16.2 | G20: 149431000 | H20: 13 | I20: 20990372 | J20: 139
A21: 19 | B21: 7 | C21: LA Lakers | D21: NBA | E21: 5182926 | F21: -17.6 | G21: 77743891 | H21: 78 | I21: 29883100 | J21: -7
A22: 20 | B22: 21 | C22: Liverpool | D22: EPL | E22: 5171351 | F22: 0.2 | G22: 129283779 | H22: 20 | I22: 24648884 | J22: 25
A23: 21 | B23: 18 | C23: Boston Celtics | D23: NBA | E23: 5087128 | F23: -6.2 | G23: 71219789 | H23: 86 | I23: 26422812 | J23: -5
A24: 22 | B24: 26 | C24: Oklahoma City Thunder | D24: NBA | E24: 5024550 | F24: 2.3 | G24: 70343704 | H24: 87 | I24: 20886632 | J24: 47
A25: 23 | B25: 38 | C25: Indiana Pacers | D25: NBA | E25: 4994377 | F25: 13.1 | G25: 69921277 | H25: 88 | I25: 21167692 | J25: 15
A26: 24 | B26: 33 | C26: Mumbai Indians | D26: IPL | E26: 4964375 | F26: 6.5 | G26: 12220000 | H26: 218 | I26: 21698248 | J26: 26
A27: 25 | B27: 58 | C27: Roma | D27: Serie A | E27: 4937720 | F27: 35.3 | G27: 123443000 | H27: 22 | I27: 17336800 | J27: 236
A28: 26 | B28: 24 | C28: LA Clippers | D28: NBA | E28: 4929758 | F28: -0.3 | G28: 73946375 | H28: 84 | I28: 21818264 | J28: 43
... A99: 97 | B99: 122 | C99: Detroit Red Wings | D99: NHL | E99: 2527685 | F99: 14.4 | G99: 68247500 | H99: 93 | I99: 12600744 | J99: 6
A100: 98 | B100: N/ rankeado | C100: Sunrisers Hyderabad | D100: IPL | E100: 2524438 | F100: 0 | G100: 6214000 | H100: 249 | I100: 0 | J100: 0
A101: 99 | B101: 112 | C101: Carolina Hurricanes | D101: NHL | E101: 2508600 | F101: 7.4 | G101: 62715000 | H101: 114 | I101: 11270896 | J101: 21
A102: 100 | B102: 139 | C102: Oakland Athletics | D102: MLB | E102: 2490997 | F102: 19.1 | G102: 77220900 | H102: 79 | I102: 10274160 | J102: 70
A103: 101 | B103: 99 | C103: Washington Capitals | D103: NHL | E103: 2488600 | F103: 0.9 | G103: 62215000 | H103: 119 | I103: 12400596 | J103: 7
A104: 102 | B104: 88 | C104: Valencia | D104: La Liga | E104: 2484453 | F104: -6.6 | G104: 62111320 | H104: 121 | I104: 0 | J104: 0
A105: 103 | B105: 63 | C105: Kings XI Punjab | D105: IPL | E105: 2478125 | F105: -26.1 | G105: 6100000 | H105: 250 | I105: 16717584 | J105: -36
A106: 104 | B106: 111 | C106: St Louis Blues | D106: NHL | E106: 2467660 | F106: 5.1 | G106: 64159167 | H106: 109 | I106: 10363912 | J106: 30
A107: 105 | B107: 93 | C107: Pittsburgh Penguins | D107: NHL | E107: 2456452 | F107: -4.5 | G107: 76150000 | H107: 80 | I107: 12233624 | J107: 4
A108: 106 | B108: 117 | C108: Dallas Stars | D108: NHL | E108: 2447917 | F108: 8.2 | G108: 58750000 | H108: 136 | I108: 10875852 | J108: 35
A109: 107 | B109: 135 | C109: Bayer Leverkusen | D109: Bundesliga | E109: 2440184 | F109: 15.2 | G109: 65884960 | H109: 102 | I109: 0 | J109: 0
A110: 108 | B110: 72 | C110: Werder Bremen | D110: Bundesliga | E110: 2436625 | F110: -17.5 | G110: 58479000 | H110: 137 | I110: 0 | J110: 0
...
