Workbook

Sheet Analises
B2: APARICOES POR LIGA NO RANKING | F2: TOP 15 ATLETAS — REMUNERACAO TOTAL | J2: ESPORTES QUE MAIS PAGAM — MEDIA TOTAL
B3: Liga | C3: Qtd. Times | D3: Sal. Medio por Jogador (USD) | F3: Atleta | G3: Remuneracao Total (US$) | H3: Esporte | J3: Esporte | K3: Media Remuneracao (US$) | L3: Qtd. Atletas
B4: AFL | C4: =COUNTIF(Folhas_de_pagamento!$D$3:$D$296,"* "&B4) -> 18 | D4: =IFERROR(AVERAGEIF(Folhas_de_pagamento!$D$3:$D$296,"* "&B4,Folhas_de_pagamento!$E$3:$E$296),0) -> 228012.83 | F4: =IFERROR(INDEX(Salários!$A$3:$A$102,MATCH(LARGE(Salários!$B$3:$B$102,1),Salários!$B$3:$B$102,0)),"-") -> Floyd Mayweather | G4: =IFERROR(LARGE(Salários!$B$3:$B$102,1),0) -> 105000000 | H4: =IFERROR(INDEX(Salários!$E$3:$E$102,MATCH(LARGE(Salários!$B$3:$B$102,1),Salários!$B$3:$B$102,0)),"-") -> Boxing | J4: Baseball | K4: =IFERROR(AVERAGEIF(Salários!$E$3:$E$102,J4,Salários!$B$3:$B$102),0) -> 21700000 | L4: =COUNTIF(Salários!$E$3:$E$102,J4) -> 27
B5: Bundesliga | C5: =COUNTIF(Folhas_de_pagamento!$D$3:$D$296,"* "&B5) -> 18 | D5: =IFERROR(AVERAGEIF(Folhas_de_pagamento!$D$3:$D$296,"* "&B5,Folhas_de_pagamento!$E$3:$E$296),0) -> 2203351.4 | F5: =IFERROR(INDEX(Salários!$A$3:$A$102,MATCH(LARGE(Salários!$B$3:$B$102,2),Salários!$B$3:$B$102,0)),"-") -> Cristiano Ronaldo | G5: =IFERROR(LARGE(Salários!$B$3:$B$102,2),0) -> 80000000 | H5: =IFERROR(INDEX(Salários!$E$3:$E$102,MATCH(LARGE(Salários!$B$3:$B$102,2),Salários!$B$3:$B$102,0)),"-") -> Soccer | J5: Basketball | K5: =IFERROR(AVERAGEIF(Salários!$E$3:$E$102,J5,Salários!$B$3:$B$102),0) -> 29272222 | L5: =COUNTIF(Salários!$E$3:$E$102,J5) -> 18
B6: CFL | C6: =COUNTIF(Folhas_de_pagamento!$D$3:$D$296,"* "&B6) -> 8 | D6: =IFERROR(AVERAGEIF(Folhas_de_pagamento!$D$3:$D$296,"* "&B6,Folhas_de_pagamento!$E$3:$E$296),0) -> 106991 | F6: =IFERROR(INDEX(Salários!$A$3:$A$102,MATCH(LARGE(Salários!$B$3:$B$102,3),Salários!$B$3:$B$102,0)),"-") -> LeBron James | G6: =IFERROR(LARGE(Salários!$B$3:$B$102,3),0) -> 72300000 | H6: =IFERROR(INDEX(Salários!$E$3:$E$102,MATCH(LARGE(Salários!$B$3:$B$102,3),Salários!$B$3:$B$102,0)),"-") -> Basketball | J6: Boxing | K6: =IFERROR(AVERAGEIF(Salários!$E$3:$E$102,J6,Salários!$B$3:$B$102),0) -> 48950000 | L6: =COUNTIF(Salários!$E$3:$E$102,J6) -> 4
B7: CSL | C7: =COUNTIF(Folhas_de_pagamento!$D$3:$D$296,"* "&B7) -> 16 | D7: =IFERROR(AVERAGEIF(Folhas_de_pagamento!$D$3:$D$296,"* "&B7,Folhas_de_pagamento!$E$3:$E$296),0) -> 318904.38 | F7: =IFERROR(INDEX(Salários!$A$3:$A$102,MATCH(LARGE(Salários!$B$3:$B$102,4),Salários!$B$3:$B$102,0)),"-") -> Lionel Messi | G7: =IFERROR(LARGE(Salários!$B$3:$B$102,4),0) -> 64700000 | H7: =IFERROR(INDEX(Salários!$E$3:$E$102,MATCH(LARGE(Salários!$B$3:$B$102,4),Salários!$B$3:$B$102,0)),"-") -> Soccer | J7: Cricket | K7: =IFERROR(AVERAGEIF(Salários!$E$3:$E$102,J7,Salários!$B$3:$B$102),0) -> 30000000 | L7: =COUNTIF(Salários!$E$3:$E$102,J7) -> 1
B8: EPL | C8: =COUNTIF(Folhas_de_pagamento!$D$3:$D$296,"* "&B8) -> 20 | D8: =IFERROR(AVERAGEIF(Folhas_de_pagamento!$D$3:$D$296,"* "&B8,Folhas_de_pagamento!$E$3:$E$296),0) -> 3453778.8 | F8: =IFERROR(INDEX(Salários!$A$3:$A$102,MATCH(LARGE(Salários!$B$3:$B$102,5),Salários!$B$3:$B$102,0)),"-") -> Kobe Bryant | G8: =IFERROR(LARGE(Salários!$B$3:$B$102,5),0) -> 61500000 | H8: =IFERROR(INDEX(Salários!$E$3:$E$102,MATCH(LARGE(Salários!$B$3:$B$102,5),Salários!$B$3:$B$102,0)),"-") -> Basketball | J8: Football | K8: =IFERROR(AVERAGEIF(Salários!$E$3:$E$102,J8,Salários!$B$3:$B$102),0) -> 22694118 | L8: =COUNTIF(Salários!$E$3:$E$102,J8) -> 17
B9: IPL | C9: =COUNTIF(Folhas_de_pagamento!$D$3:$D$296,"* "&B9) -> 9 | D9: =IFERROR(AVERAGEIF(Folhas_de_pagamento!$D$3:$D$296,"* "&B9,Folhas_de_pagamento!$E$3:$E$296),0) -> 3650346.2 | F9: =IFERROR(INDEX(Salários!$A$3:$A$102,MATCH(LARGE(Salários!$B$3:$B$102,6),Salários!$B$3:$B$102,0)),"-") -> Tiger Woods | G9: =IFERROR(LARGE(Salários!$B$3:$B$102,6),0) -> 61200000 | H9: =IFERROR(INDEX(Salários!$E$3:$E$102,MATCH(LARGE(Salários!$B$3:$B$102,6),Salários!$B$3:$B$102,0)),"-") -> Golf | J9: Golf | K9: =IFERROR(AVERAGEIF(Salários!$E$3:$E$102,J9,Salários!$B$3:$B$102),0) -> 35520000 | L9: =COUNTIF(Salários!$E$3:$E$102,J9) -> 5
B10: La Liga | C10: =COUNTIF(Folhas_de_pagamento!$D$3:$D$296,"* "&B10) -> 20 | D10: =IFERROR(AVERAGEIF(Folhas_de_pagamento!$D$3:$D$296,"* "&B10,Folhas_de_pagamento!$E$3:$E$296),0) -> 1831734.5 | F10: =IFERROR(INDEX(Salários!$A$3:$A$102,MATCH(LARGE(Salários!$B$3:$B$102,7),Salários!$B$3:$B$102,0)),"-") -> Roger Federer | G10: =IFERROR(LARGE(Salários!$B$3:$B$102,7),0) -> 56200000 | H10: =IFERROR(INDEX(Salários!$E$3:$E$102,MATCH(LARGE(Salários!$B$3:$B$102,7),Salários!$B$3:$B$102,0)),"-") -> Tennis | J10: Racing | K10: =IFERROR(AVERAGEIF(Salários!$E$3:$E$102,J10,Salários!$B$3:$B$102),0) -> 25016667 | L10: =COUNTIF(Salários!$E$3:$E$102,J10) -> 6
B11: MLB | C11: =COUNTIF(Folhas_de_pagamento!$D$3:$D$296,"* "&B11) -> 30 | D11: =IFERROR(AVERAGEIF(Folhas_de_pagamento!$D$3:$D$296,"* "&B11,Folhas_de_pagamento!$E$3:$E$296),0) -> 3935364.2 | F11: =IFERROR(INDEX(Salários!$A$3:$A$102,MATCH(LARGE(Salários!$B$3:$B$102,8),Salários!$B$3:$B$102,0)),"-") -> Phil Mickelson | G11: =IFERROR(LARGE(Salários!$B$3:$B$102,8),0) -> 53200000 | H11: =IFERROR(INDEX(Salários!$E$3:$E$102,MATCH(LARGE(Salários!$B$3:$B$102,8),Salários!$B$3:$B$102,0)),"-") -> Golf | J11: Soccer | K11: =IFERROR(AVERAGEIF(Salários!$E$3:$E$102,J11,Salários!$B$3:$B$102),0) -> 31500000 | L11: =COUNTIF(Salários!$E$3:$E$102,J11) -> 15
B12: MLS | C12: =COUNTIF(Folhas_de_pagamento!$D$3:$D$296,"* "&B12) -> 19 | D12: =IFERROR(AVERAGEIF(Folhas_de_pagamento!$D$3:$D$296,"* "&B12,Folhas_de_pagamento!$E$3:$E$296),0) -> 196291.53 | F12: =IFERROR(INDEX(Salários!$A$3:$A$102,MATCH(LARGE(Salários!$B$3:$B$102,9),Salários!$B$3:$B$102,0)),"-") -> Rafael Nadal | G12: =IFERROR(LARGE(Salários!$B$3:$B$102,9),0) -> 44500000 | H12: =IFERROR(INDEX(Salários!$E$3:$E$102,MATCH(LARGE(Salários!$B$3:$B$102,9),Salários!$B$3:$B$102,0)),"-") -> Tennis | J12: Tennis | K12: =IFERROR(AVERAGEIF(Salários!$E$3:$E$102,J12,Salários!$B$3:$B$102),0) -> 33966667 | L12: =COUNTIF(Salários!$E$3:$E$102,J12) -> 6
B13: NBA | C13: =COUNTIF(Folhas_de_pagamento!$D$3:$D$296,"* "&B13) -> 30 | D13: =IFERROR(AVERAGEIF(Folhas_de_pagamento!$D$3:$D$296,"* "&B13,Folhas_de_pagamento!$E$3:$E$296),0) -> 4530724.1 | F13: =IFERROR(INDEX(Salários!$A$3:$A$102,MATCH(LARGE(Salários!$B$3:$B$102,10),Salários!$B$3:$B$102,0)),"-") -> Matt Ryan | G13: =IFERROR(LARGE(Salários!$B$3:$B$102,10),0) -> 43800000 | H13: =IFERROR(INDEX(Salários!$E$3:$E$102,MATCH(LARGE(Salários!$B$3:$B$102,10),Salários!$B$3:$B$102,0)),"-") -> Football | J13: Track | K13: =IFERROR(AVERAGEIF(Salários!$E$3:$E$102,J13,Salários!$B$3:$B$102),0) -> 23200000 | L13: =COUNTIF(Salários!$E$3:$E$102,J13) -> 1
B14: NFL | C14: =COUNTIF(Folhas_de_pagamento!$D$3:$D$296,"* "&B14) -> 32 | D14: =IFERROR(AVERAGEIF(Folhas_de_pagamento!$D$3:$D$296,"* "&B14,Folhas_de_pagamento!$E$3:$E$296),0) -> 1955966.2 | F14: =IFERROR(INDEX(Salários!$A$3:$A$102,MATCH(LARGE(Salários!$B$3:$B$102,11),Salários!$B$3:$B$102,0)),"-") -> Manny Pacquiao | G14: =IFERROR(LARGE(Salários!$B$3:$B$102,11),0) -> 41800000 | H14: =IFERROR(INDEX(Salários!$E$3:$E$102,MATCH(LARGE(Salários!$B$3:$B$102,11),Salários!$B$3:$B$102,0)),"-") -> Boxing
B15: NHL | C15: =COUNTIF(Folhas_de_pagamento!$D$3:$D$296,"* "&B15) -> 30 | D15: =IFERROR(AVERAGEIF(Folhas_de_pagamento!$D$3:$D$296,"* "&B15,Folhas_de_pagamento!$E$3:$E$296),0) -> 2429934.7 | F15: =IFERROR(INDEX(Salários!$A$3:$A$102,MATCH(LARGE(Salários!$B$3:$B$102,12),Salários!$B$3:$B$102,0)),"-") -> Zlatan Ibrahimovic | G15: =IFERROR(LARGE(Salários!$B$3:$B$102,12),0) -> 40400000 | H15: =IFERROR(INDEX(Salários!$E$3:$E$102,MATCH(LARGE(Salários!$B$3:$B$102,12),Salários!$B$3:$B$102,0)),"-") -> Soccer
B16: NPB | C16: =COUNTIF(Folhas_de_pagamento!$D$3:$D$296,"* "&B16) -> 12 | D16: =IFERROR(AVERAGEIF(Folhas_de_pagamento!$D$3:$D$296,"* "&B16,Folhas_de_pagamento!$E$3:$E$296),0) -> 604940.08 | F16: =IFERROR(INDEX(Salários!$A$3:$A$102,MATCH(LARGE(Salários!$B$3:$B$102,13),Salários!$B$3:$B$102,0)),"-") -> Derrick Rose | G16: =IFERROR(LARGE(Salários!$B$3:$B$102,13),0) -> 36600000 | H16: =IFERROR(INDEX(Salários!$E$3:$E$102,MATCH(LARGE(Salários!$B$3:$B$102,13),Salários!$B$3:$B$102,0)),"-") -> Basketball | J16: VISAO GERAL — FOLHA SALARIAL DOS TIMES
B17: SPL | C17: =COUNTIF(Folhas_de_pagamento!$D$3:$D$296,"* "&B17) -> 12 | D17: =IFERROR(AVERAGEIF(Folhas_de_pagamento!$D$3:$D$296,"* "&B17,Folhas_de_pagamento!$E$3:$E$296),0) -> 277709.92 | F17: =IFERROR(INDEX(Salários!$A$3:$A$102,MATCH(LARGE(Salários!$B$3:$B$102,14),Salários!$B$3:$B$102,0)),"-") -> Gareth Bale | G17: =IFERROR(LARGE(Salários!$B$3:$B$102,14),0) -> 36400000 | H17: =IFERROR(INDEX(Salários!$E$3:$E$102,MATCH(LARGE(Salários!$B$3:$B$102,14),Salários!$B$3:$B$102,0)),"-") -> Soccer | J17: Indicador | K17: Folha Salarial Total | L17: Sal. Medio por Jogador
B18: Serie A | C18: =COUNTIF(Folhas_de_pagamento!$D$3:$D$296,"* "&B18) -> 20 | D18: =IFERROR(AVERAGEIF(Folhas_de_pagamento!$D$3:$D$296,"* "&B18,Folhas_de_pagamento!$E$3:$E$296),0) -> 1987535.3 | F18: =IFERROR(INDEX(Salários!$A$3:$A$102,MATCH(LARGE(Salários!$B$3:$B$102,15),Salários!$B$3:$B$102,0)),"-") -> Radamel Falcao | G18: =IFERROR(LARGE(Salários!$B$3:$B$102,15),0) -> 35400000 | H18: =IFERROR(INDEX(Salários!$E$3:$E$102,MATCH(LARGE(Salários!$B$3:$B$102,15),Salários!$B$3:$B$102,0)),"-") -> Soccer | J18: Media geral dos times | K18: =AVERAGE(Folhas_de_pagamento!$G$3:$G$296) -> 54929687 | L18: =AVERAGE(Folhas_de_pagamento!$E$3:$E$296) -> 2149081.6
B19: TOTAL | C19: =SUM(C4:C18) -> 294 | D19: =IFERROR(AVERAGE(Folhas_de_pagamento!$E$3:$E$296),0) -> 2149081.6 | J19: Maior valor | K19: =LARGE(Folhas_de_pagamento!$G$3:$G$296,1) -> 241128402 | L19: =LARGE(Folhas_de_pagamento!$E$3:$E$296,1) -> 8109912
J20: Menor valor | K20: =SMALL(Folhas_de_pagamento!$G$3:$G$296,1) -> 1440000 | L20: =SMALL(Folhas_de_pagamento!$E$3:$E$296,1) -> 42353
B21: LIGAS QUE MAIS PAGAM POR JOGADOR | F21: TOP 15 ATLETAS — MAIOR SALARIO | J21: Times acima da media | K21: =COUNTIF(Folhas_de_pagamento!$G$3:$G$296,">"&AVERAGE(Folhas_de_pagamento!$G$3:$G$296)) -> 143 | L21: =COUNTIF(Folhas_de_pagamento!$E$3:$E$296,">"&AVERAGE(Folhas_de_pagamento!$E$3:$E$296)) -> 134
B22: Liga | C22: Sal. Medio / Jogador (USD) | D22: Posicao | F22: Atleta | G22: Salario / Premiacoes (US$) | H22: Esporte | J22: Times abaixo da media | K22: =COUNTIF(Folhas_de_pagamento!$G$3:$G$296,"<"&AVERAGE(Folhas_de_pagamento!$G$3:$G$296)) -> 151 | L22: =COUNTIF(Folhas_de_pagamento!$E$3:$E$296,"<"&AVERAGE(Folhas_de_pagamento!$E$3:$E$296)) -> 160
B23: AFL | C23: =IFERROR(AVERAGEIF(Folhas_de_pagamento!$D$3:$D$296,"* "&B23,Folhas_de_pagamento!$E$3:$E$296),0) -> 228012.83 | D23: =IFERROR(RANK(C23,$C$23:$C$37,0),"-") -> 13 | F23: =IFERROR(INDEX(Salários!$A$3:$A$102,MATCH(LARGE(Salários!$C$3:$C$102,1),Salários!$C$3:$C$102,0)),"-") -> Floyd Mayweather | G23: =IFERROR(LARGE(Salários!$C$3:$C$102,1),0) -> 105000000 | H23: =IFERROR(INDEX(Salários!$E$3:$E$102,MATCH(LARGE(Salários!$C$3:$C$102,1),Salários!$C$3:$C$102,0)),"-") -> Boxing | J23: Time com maior folha | K23: =IFERROR(INDEX(Folhas_de_pagamento!$C$3:$C$296,MATCH(LARGE(Folhas_de_pagamento!$G$3:$G$296,1),Folhas_de_pagamento!$G$3:$G$296,0)),"-") -> Los Angeles Dodgers | L23: =IFERROR(INDEX(Folhas_de_pagamento!$C$3:$C$296,MATCH(LARGE(Folhas_de_pagamento!$E$3:$E$296,1),Folhas_de_pagamento!$E$3:$E$296,0)),"-") -> Manchester City
B24: Bundesliga | C24: =IFERROR(AVERAGEIF(Folhas_de_pagamento!$D$3:$D$296,"* "&B24,Folhas_de_pagamento!$E$3:$E$296),0) -> 2203351.4 | D24: =IFERROR(RANK(C24,$C$23:$C$37,0),"-") -> 6 | F24: =IFERROR(INDEX(Salários!$A$3:$A$102,MATCH(LARGE(Salários!$C$3:$C$102,2),Salários!$C$3:$C$102,0)),"-") -> Cristiano Ronaldo | G24: =IFERROR(LARGE(Salários!$C$3:$C$102,2),0) -> 52000000 | H24: =IFERROR(INDEX(Salários!$E$3:$E$102,MATCH(LARGE(Salários!$C$3:$C$102,2),Salários!$C$3:$C$102,0)),"-") -> Soccer | J24: Time com menor folha | K24: =IFERROR(INDEX(Folhas_de_pagamento!$C$3:$C$296,MATCH(SMALL(Folhas_de_pagamento!$G$3:$G$296,1),Folhas_de_pagamento!$G$3:$G$296,0)),"-") -> Shanghai Dongya | L24: =IFERROR(INDEX(Folhas_de_pagamento!$C$3:$C$296,MATCH(SMALL(Folhas_de_pagamento!$E$3:$E$296,1),Folhas_de_pagamento!$E$3:$E$296,0)),"-") -> Shanghai Dongya
B25: CFL | C25: =IFERROR(AVERAGEIF(Folhas_de_pagamento!$D$3:$D$296,"* "&B25,Folhas_de_pagamento!$E$3:$E$296),0) -> 106991 | D25: =IFERROR(RANK(C25,$C$23:$C$37,0),"-") -> 15 | F25: =IFERROR(INDEX(Salários!$A$3:$A$102,MATCH(LARGE(Salários!$C$3:$C$102,3),Salários!$C$3:$C$102,0)),"-") -> Matt Ryan | G25: =IFERROR(LARGE(Salários!$C$3:$C$102,3),0) -> 42000000 | H25: =IFERROR(INDEX(Salários!$E$3:$E$102,MATCH(LARGE(Salários!$C$3:$C$102,3),Salários!$C$3:$C$102,0)),"-") -> Football
B26: CSL | C26: =IFERROR(AVERAGEIF(Folhas_de_pagamento!$D$3:$D$296,"* "&B26,Folhas_de_pagamento!$E$3:$E$296),0) -> 318904.38 | D26: =IFERROR(RANK(C26,$C$23:$C$37,0),"-") -> 11 | F26: =IFERROR(INDEX(Salários!$A$3:$A$102,MATCH(LARGE(Salários!$C$3:$C$102,4),Salários!$C$3:$C$102,0)),"-") -> Lionel Messi | G26: =IFERROR(LARGE(Salários!$C$3:$C$102,4),0) -> 41700000 | H26: =IFERROR(INDEX(Salários!$E$3:$E$102,MATCH(LARGE(Salários!$C$3:$C$102,4),Salários!$C$3:$C$102,0)),"-") -> Soccer
B27: EPL | C27: =IFERROR(AVERAGEIF(Folhas_de_pagamento!$D$3:$D$296,"* "&B27,Folhas_de_pagamento!$E$3:$E$296),0) -> 3453778.8 | D27: =IFERROR(RANK(C27,$C$23:$C$37,0),"-") -> 4 | F27: =IFERROR(INDEX(Salários!$A$3:$A$102,MATCH(LARGE(Salários!$C$3:$C$102,5),Salários!$C$3:$C$102,0)),"-") -> Manny Pacquiao | G27: =IFERROR(LARGE(Salários!$C$3:$C$102,5),0) -> 41000000 | H27: =IFERROR(INDEX(Salários!$E$3:$E$102,MATCH(LARGE(Salários!$C$3:$C$102,5),Salários!$C$3:$C$102,0)),"-") -> Boxing | J27: VISAO GERAL — ATLETAS
B28: IPL | C28: =IFERROR(AVERAGEIF(Folhas_de_pagamento!$D$3:$D$296,"* "&B28,Folhas_de_pagamento!$E$3:$E$296),0) -> 3650346.2 | D28: =IFERROR(RANK(C28,$C$23:$C$37,0),"-") -> 3 | F28: =IFERROR(INDEX(Salários!$A$3:$A$102,MATCH(LARGE(Salários!$C$3:$C$102,6),Salários!$C$3:$C$102,0)),"-") -> Zlatan Ibrahimovic | G28: =IFERROR(LARGE(Salários!$C$3:$C$102,6),0) -> 36400000 | H28: =IFERROR(INDEX(Salários!$E$3:$E$102,MATCH(LARGE(Salários!$C$3:$C$102,6),Salários!$C$3:$C$102,0)),"-") -> Soccer | J28: Indicador | K28: Remuneracao Total | L28: Patrocinios
B29: La Liga | C29: =IFERROR(AVERAGEIF(Folhas_de_pagamento!$D$3:$D$296,"* "&B29,Folhas_de_pagamento!$E$3:$E$296),0) -> 1831734.5 | D29: =IFERROR(RANK(C29,$C$23:$C$37,0),"-") -> 9 | F29: =IFERROR(INDEX(Salários!$A$3:$A$102,MATCH(LARGE(Salários!$C$3:$C$102,7),Salários!$C$3:$C$102,0)),"-") -> Radamel Falcao | G29: =IFERROR(LARGE(Salários!$C$3:$C$102,7),0) -> 32400000 | H29: =IFERROR(INDEX(Salários!$E$3:$E$102,MATCH(LARGE(Salários!$C$3:$C$102,7),Salários!$C$3:$C$102,0)),"-") -> Soccer | J29: Media geral | K29: =AVERAGE(Salários!$B$3:$B$102) -> 27516000 | L29: =IFERROR(AVERAGEIF(Salários!$D$3:$D$102,">"&0),0) -> 7489747.5
B30: MLB | C30: =IFERROR(AVERAGEIF(Folhas_de_pagamento!$D$3:$D$296,"* "&B30,Folhas_de_pagamento!$E$3:$E$296),0) -> 3935364.2 | D30: =IFERROR(RANK(C30,$C$23:$C$37,0),"-") -> 2 | F30: =IFERROR(INDEX(Salários!$A$3:$A$102,MATCH(LARGE(Salários!$C$3:$C$102,8),Salários!$C$3:$C$102,0)),"-") -> Matthew Stafford | G30: =IFERROR(LARGE(Salários!$C$3:$C$102,8),0) -> 31500000 | H30: =IFERROR(INDEX(Salários!$E$3:$E$102,MATCH(LARGE(Salários!$C$3:$C$102,8),Salários!$C$3:$C$102,0)),"-") -> Football | J30: Maior valor | K30: =LARGE(Salários!$B$3:$B$102,1) -> 105000000 | L30: =LARGE(Salários!$D$3:$D$102,1) -> 55000000
B31: MLS | C31: =IFERROR(AVERAGEIF(Folhas_de_pagamento!$D$3:$D$296,"* "&B31,Folhas_de_pagamento!$E$3:$E$296),0) -> 196291.53 | D31: =IFERROR(RANK(C31,$C$23:$C$37,0),"-") -> 14 | F31: =IFERROR(INDEX(Salários!$A$3:$A$102,MATCH(LARGE(Salários!$C$3:$C$102,9),Salários!$C$3:$C$102,0)),"-") -> Kobe Bryant | G31: =IFERROR(LARGE(Salários!$C$3:$C$102,9),0) -> 30500000 | H31: =IFERROR(INDEX(Salários!$E$3:$E$102,MATCH(LARGE(Salários!$C$3:$C$102,9),Salários!$C$3:$C$102,0)),"-") -> Basketball | J31: Atleta lider | K31: =IFERROR(INDEX(Salários!$A$3:$A$102,MATCH(LARGE(Salários!$B$3:$B$102,1),Salários!$B$3:$B$102,0)),"-") -> Floyd Mayweather | L31: =IFERROR(INDEX(Salários!$A$3:$A$102,MATCH(LARGE(Salários!$D$3:$D$102,1),Salários!$D$3:$D$102,0)),"-") -> Tiger Woods
B32: NBA | C32: =IFERROR(AVERAGEIF(Folhas_de_pagamento!$D$3:$D$296,"* "&B32,Folhas_de_pagamento!$E$3:$E$296),0) -> 4530724.1 | D32: =IFERROR(RANK(C32,$C$23:$C$37,0),"-") -> 1 | F32: =IFERROR(INDEX(Salários!$A$3:$A$102,MATCH(LARGE(Salários!$C$3:$C$102,10),Salários!$C$3:$C$102,0)),"-") -> Lewis Hamilton | G32: =IFERROR(LARGE(Salários!$C$3:$C$102,10),0) -> 29000000 | H32: =IFERROR(INDEX(Salários!$E$3:$E$102,MATCH(LARGE(Salários!$C$3:$C$102,10),Salários!$C$3:$C$102,0)),"-") -> Racing | J32: Acima da media | K32: =COUNTIF(Salários!$B$3:$B$102,">"&AVERAGE(Salários!$B$3:$B$102)) -> 25 | L32: =COUNTIF(Salários!$D$3:$D$102,">"&AVERAGE(Salários!$D$3:$D$102)) -> 28
B33: NFL | C33: =IFERROR(AVERAGEIF(Folhas_de_pagamento!$D$3:$D$296,"* "&B33,Folhas_de_pagamento!$E$3:$E$296),0) -> 1955966.2 | D33: =IFERROR(RANK(C33,$C$23:$C$37,0),"-") -> 8 | F33: =IFERROR(INDEX(Salários!$A$3:$A$102,MATCH(LARGE(Salários!$C$3:$C$102,11),Salários!$C$3:$C$102,0)),"-") -> Lewis Hamilton | G33: =IFERROR(LARGE(Salários!$C$3:$C$102,11),0) -> 29000000 | H33: =IFERROR(INDEX(Salários!$E$3:$E$102,MATCH(LARGE(Salários!$C$3:$C$102,11),Salários!$C$3:$C$102,0)),"-") -> Racing | J33: Abaixo da media | K33: =COUNTIF(Salários!$B$3:$B$102,"<"&AVERAGE(Salários!$B$3:$B$102)) -> 75 | L33: =COUNTIF(Salários!$D$3:$D$102,">"&0) -> 99
B34: NHL | C34: =IFERROR(AVERAGEIF(Folhas_de_pagamento!$D$3:$D$296,"* "&B34,Folhas_de_pagamento!$E$3:$E$296),0) -> 2429934.7 | D34: =IFERROR(RANK(C34,$C$23:$C$37,0),"-") -> 5 | F34: =IFERROR(INDEX(Salários!$A$3:$A$102,MATCH(LARGE(Salários!$C$3:$C$102,12),Salários!$C$3:$C$102,0)),"-") -> Gareth Bale | G34: =IFERROR(LARGE(Salários!$C$3:$C$102,12),0) -> 25400000 | H34: =IFERROR(INDEX(Salários!$E$3:$E$102,MATCH(LARGE(Salários!$C$3:$C$102,12),Salários!$C$3:$C$102,0)),"-") -> Soccer
B35: NPB | C35: =IFERROR(AVERAGEIF(Folhas_de_pagamento!$D$3:$D$296,"* "&B35,Folhas_de_pagamento!$E$3:$E$296),0) -> 604940.08 | D35: =IFERROR(RANK(C35,$C$23:$C$37,0),"-") -> 10 | F35: =IFERROR(INDEX(Salários!$A$3:$A$102,MATCH(LARGE(Salários!$C$3:$C$102,13),Salários!$C$3:$C$102,0)),"-") -> Cliff Lee | G35: =IFERROR(LARGE(Salários!$C$3:$C$102,13),0) -> 25100000 | H35: =IFERROR(INDEX(Salários!$E$3:$E$102,MATCH(LARGE(Salários!$C$3:$C$102,13),Salários!$C$3:$C$102,0)),"-") -> Baseball
B36: SPL | C36: =IFERROR(AVERAGEIF(Folhas_de_pagamento!$D$3:$D$296,"* "&B36,Folhas_de_pagamento!$E$3:$E$296),0) -> 277709.92 | D36: =IFERROR(RANK(C36,$C$23:$C$37,0),"-") -> 12 | F36: =IFERROR(INDEX(Salários!$A$3:$A$102,MATCH(LARGE(Salários!$C$3:$C$102,14),Salários!$C$3:$C$102,0)),"-") -> Zack Greinke | G36: =IFERROR(LARGE(Salários!$C$3:$C$102,14),0) -> 24400000 | H36: =IFERROR(INDEX(Salários!$E$3:$E$102,MATCH(LARGE(Salários!$C$3:$C$102,14),Salários!$C$3:$C$102,0)),"-") -> Baseball
B37: Serie A | C37: =IFERROR(AVERAGEIF(Folhas_de_pagamento!$D$3:$D$296,"* "&B37,Folhas_de_pagamento!$E$3:$E$296),0) -> 1987535.3 | D37: =IFERROR(RANK(C37,$C$23:$C$37,0),"-") -> 7 | F37: =IFERROR(INDEX(Salários!$A$3:$A$102,MATCH(LARGE(Salários!$C$3:$C$102,15),Salários!$C$3:$C$102,0)),"-") -> Wladimir Klitschko | G37: =IFERROR(LARGE(Salários!$C$3:$C$102,15),0) -> 24000000 | H37: =IFERROR(INDEX(Salários!$E$3:$E$102,MATCH(LARGE(Salários!$C$3:$C$102,15),Salários!$C$3:$C$102,0)),"-") -> Boxing
B40: TOP 10 TIMES QUE MAIS CRESCERAM A FOLHA | F40: TOP 15 ATLETAS — MAIOR PATROCINIO
B41: Time | C41: Liga | D41: % Variacao Ano Anterior | F41: Atleta | G41: Patrocinios (US$) | H41: Esporte
B42: =IFERROR(INDEX(Folhas_de_pagamento!$C$3:$C$296,MATCH(LARGE(Folhas_de_pagamento!$F$3:$F$296,1),Folhas_de_pagamento!$F$3:$F$296,0)),"-") -> Houston Astros | C42: =IFERROR(TRIM(INDEX(Folhas_de_pagamento!$D$3:$D$296,MATCH(LARGE(Folhas_de_pagamento!$F$3:$F$296,1),Folhas_de_pagamento!$F$3:$F$296,0))),"-") -> MLB | D42: =IFERROR(LARGE(Folhas_de_pagamento!$F$3:$F$296,1)/100,0) -> 0.00966 | F42: =IFERROR(INDEX(Salários!$A$3:$A$102,MATCH(LARGE(Salários!$D$3:$D$102,1),Salários!$D$3:$D$102,0)),"-") -> Tiger Woods | G42: =IFERROR(LARGE(Salários!$D$3:$D$102,1),0) -> 55000000 | H42: =IFERROR(INDEX(Salários!$E$3:$E$102,MATCH(LARGE(Salários!$D$3:$D$102,1),Salários!$D$3:$D$102,0)),"-") -> Golf
B43: =IFERROR(INDEX(Folhas_de_pagamento!$C$3:$C$296,MATCH(LARGE(Folhas_de_pagamento!$F$3:$F$296,2),Folhas_de_pagamento!$F$3:$F$296,0)),"-") -> Seattle Sounders | C43: =IFERROR(TRIM(INDEX(Folhas_de_pagamento!$D$3:$D$296,MATCH(LARGE(Folhas_de_pagamento!$F$3:$F$296,2),Folhas_de_pagamento!$F$3:$F$296,0))),"-") -> MLS | D43: =IFERROR(LARGE(Folhas_de_pagamento!$F$3:$F$296,2)/100,0) -> 0.00896 | F43: =IFERROR(INDEX(Salários!$A$3:$A$102,MATCH(LARGE(Salários!$D$3:$D$102,2),Salários!$D$3:$D$102,0)),"-") -> LeBron James | G43: =IFERROR(LARGE(Salários!$D$3:$D$102,2),0) -> 53000000 | H43: =IFERROR(INDEX(Salários!$E$3:$E$102,MATCH(LARGE(Salários!$D$3:$D$102,2),Salários!$D$3:$D$102,0)),"-") -> Basketball
...

Sheet Salários
A1: Ranking de Atletas com Maiores Remuneracoes (2014)
A2: Atleta | B2: Remuneracao Total 2014 (US$) | C2: Salario / Premiacoes (US$) | D2: Patrocinios (US$) | E2: Esporte
A3: Floyd Mayweather | B3: 105000000 | C3: 105000000 | E3: Boxing
A4: Cristiano Ronaldo | B4: 80000000 | C4: 52000000 | D4: 28000000 | E4: Soccer
A5: LeBron James | B5: 72300000 | C5: 19300000 | D5: 53000000 | E5: Basketball
A6: Lionel Messi | B6: 64700000 | C6: 41700000 | D6: 23000000 | E6: Soccer
A7: Kobe Bryant | B7: 61500000 | C7: 30500000 | D7: 31000000 | E7: Basketball
A8: Tiger Woods | B8: 61200000 | C8: 6200000 | D8: 55000000 | E8: Golf
A9: Roger Federer | B9: 56200000 | C9: 4200000 | D9: 52000000 | E9: Tennis
A10: Phil Mickelson | B10: 53200000 | C10: 5200000 | D10: 48000000 | E10: Golf
A11: Rafael Nadal | B11: 44500000 | C11: 14500000 | D11: 30000000 | E11: Tennis
A12: Matt Ryan | B12: 43800000 | C12: 42000000 | D12: 1800000 | E12: Football
A13: Manny Pacquiao | B13: 41800000 | C13: 41000000 | D13: 800000 | E13: Boxing
A14: Zlatan Ibrahimovic | B14: 40400000 | C14: 36400000 | D14: 4000000 | E14: Soccer
A15: Derrick Rose | B15: 36600000 | C15: 17600000 | D15: 19000000 | E15: Basketball
... A102: Luis Suarez | B102: 17300000 | C102: 13300000 | D102: 4000000 | E102: Soccer

Sheet Folhas_de_pagamento
A1: Ranking de Times com Maiores Folhas de Pagamento
A2: Ranking | B2: Rank. Ano Anterior | C2: Time | D2: Liga | E2: Sal. Medio/Jogador (US$) | F2: % Variacao Ano Ant. | G2: Folha Salarial (US$) | H2: Rank. Folha Salarial | I2: Ganho Medio 5 Anos (US$) | J2: % Variacao 5 Anos
A3: 1 | B3: 1 | C3: Manchester City | D3: EPL | E3: 8109912 | F3: 0.006 | G3: 202747812 | H3: 3 | I3: 31660772 | J3: 0.0265
A4: 2 | B4: 5 | C4: New York Yankees | D4: MLB | E4: 8031948 | F4: 0.123 | G4: 208830659 | H4: 2 | I4: 35789052 | J4: 0.05
A5: 3 | B5: 2 | C5: Los Angeles Dodgers | D5: MLB | E5: 7778336 | F5: 0.041 | G5: 241128402 | H5: 1 | I5: 26226200 | J5: 0.79
A6: 4 | B6: 3 | C6: Real Madrid | D6: La Liga | E6: 7586438 | F6: 0.037 | G6: 189660944 | H6: 5 | I6: 36995660 | J6: 0.09
A7: 5 | B7: 4 | C7: Barcelona | D7: La Liga | E7: 7446562 | F7: 0.024 | G7: 193610600 | H7: 4 | I7: 37975600 | J7: 0.12
A8: 6 | B8: 16 | C8: Brooklyn Nets | D8: NBA | E8: 6814067 | F8: 0.236 | G8: 102211009 | H8: 51 | I8: 24108812 | J8: 0.65
A9: 7 | B9: 9 | C9: Bayern Munich | D9: Bundesliga | E9: 6689311 | F9: 0.087 | G9: 173922091 | H9: 7 | I9: 29919552 | J9: 0.36
A10: 8 | B10: 12 | C10: Manchester United | D10: EPL | E10: 6566775 | F10: 0.089 | G10: 164169367 | H10: 8 | I10: 27985256 | J10: 0.38
A11: 9 | B11: 19 | C11: Chicago Bulls | D11: NBA | E11: 6055463 | F11: 0.145 | G11: 78721016 | H11: 76 | I11: 24709880 | J11: 0.51
A12: 10 | B12: 8 | C12: Chelsea | D12: EPL | E12: 6053686 | F12: -0.03 | G12: 151342140 | H12: 12 | I12: 30990544 | J12: 0.03
A13: 11 | B13: 15 | C13: Arsenal | D13: EPL | E13: 5928172 | F13: 0.051 | G13: 148204312 | H13: 15 | I13: 25892620 | J13: 0.38
A14: 12 | B14: 20 | C14: NY Knicks | D14: NBA | E14: 5867808 | F14: 0.135 | G14: 88017120 | H14: 67 | I14: 24425648 | J14: 0.1
... A99: 97 | B99: 122 | C99: Detroit Red Wings | D99: NHL | E99: 2527685 | F99: 0.144 | G99: 68247500 | H99: 93 | I99: 12600744 | J99: 0.06
A100: 98 | B100: N/ rankeado | C100: Sunrisers Hyderabad | D100: IPL | E100: 2524438 | F100: 0 | G100: 6214000 | H100: 249 | I100: 0 | J100: 0
A101: 99 | B101: 112 | C101: Carolina Hurricanes | D101: NHL | E101: 2508600 | F101: 0.074 | G101: 62715000 | H101: 114 | I101: 11270896 | J101: 0.21
A102: 100 | B102: 139 | C102: Oakland Athletics | D102: MLB | E102: 2490997 | F102: 0.191 | G102: 77220900 | H102: 79 | I102: 10274160 | J102: 0.7
A103: 101 | B103: 99 | C103: Washington Capitals | D103: NHL | E103: 2488600 | F103: 0.009 | G103: 62215000 | H103: 119 | I103: 12400596 | J103: 0.07
A104: 102 | B104: 88 | C104: Valencia | D104: La Liga | E104: 2484453 | F104: -0.066 | G104: 62111320 | H104: 121 | I104: 0 | J104: 0
A105: 103 | B105: 63 | C105: Kings XI Punjab | D105: IPL | E105: 2478125 | F105: -0.261 | G105: 6100000 | H105: 250 | I105: 16717584 | J105: -0.36
A106: 104 | B106: 111 | C106: St Louis Blues | D106: NHL | E106: 2467660 | F106: 0.051 | G106: 64159167 | H106: 109 | I106: 10363912 | J106: 0.3
A107: 105 | B107: 93 | C107: Pittsburgh Penguins | D107: NHL | E107: 2456452 | F107: -0.045 | G107: 76150000 | H107: 80 | I107: 12233624 | J107: 0.04
A108: 106 | B108: 117 | C108: Dallas Stars | D108: NHL | E108: 2447917 | F108: 0.082 | G108: 58750000 | H108: 136 | I108: 10875852 | J108: 0.35
A109: 107 | B109: 135 | C109: Bayer Leverkusen | D109: Bundesliga | E109: 2440184 | F109: 0.152 | G109: 65884960 | H109: 102 | I109: 0 | J109: 0
A110: 108 | B110: 72 | C110: Werder Bremen | D110: Bundesliga | E110: 2436625 | F110: -0.175 | G110: 58479000 | H110: 137 | I110: 0 | J110: 0
A111: 109 | B111: 73 | C111: Sunderland | D111: EPL | E111: 2431002 | F111: -0.154 | G111: 60775039 | H111: 127 | I111: 11160968 | J111: 0.74
A112: 110 | B112: 125 | C112: Toronto Maple Leafs | D112: NHL | E112: 2427800 | F112: 0.104 | G112: 60695000 | H112: 128 | I112: 12086932 | J112: -0.1
... A132: 130 | B132: 145 | C132: New Orleans Saints | D132: NFL | E132: 2195643 | F132: 0.078 | G132: 116369072 | H132: 27 | I132: 11529544 | J132: -0.02
A133: 131 | B133: N/ rankeado | C133: West Ham | D133: EPL | E133: 2186148 | F133: 0 | G133: 54653688 | H133: 145 | I133: 9759464 | J133: -0.2
A134: 132 | B134: 105 | C134: Kansas City Chiefs | D134: NFL | E134: 2171845 | F134: -0.104 | G134: 115107799 | H134: 28 | I134: 9889256 | J134: 0.45
A135: 133 | B135: 152 | C135: Tennessee Titans | D135: NFL | E135: 2155103 | F135: 0.075 | G135: 114220438 | H135: 29 | I135: 10318464 | J135: -0.04
A136: 134 | B136: 132 | C136: Green Bay Packers | D136: NFL | E136: 2153098 | F136: 0.003 | G136: 114114214 | H136: 30 | I136: 10799620 | J136: 0.35
A137: 135 | B137: 134 | C137: Philadelphia Eagles | D137: NFL | E137: 2138436 | F137: 0.003 | G137: 113337103 | H137: 31 | I137: 10756408 | J137: 0.11
A138: 136 | B138: 141 | C138: Sevilla | D138: La Liga | E138: 2113136 | F138: 0.009 | G138: 52828406 | H138: 150 | I138: 0 | J138: 0
A139: 137 | B139: 142 | C139: Pittsburgh Steelers | D139: NFL | E139: 2095226 | F139: 0.01 | G139: 111046989 | H139: 34 | I139: 11575980 | J139: 0.01
A140: 138 | B140: 157 | C140: Cincinnati Bengals | D140: NFL | E140: 2090424 | F140: 0.09 | G140: 110792462 | H140: 35 | I140: 9324224 | J140: 0.18
A141: 139 | B141: 116 | C141: New York Giants | D141: NFL | E141: 2089848 | F141: -0.083 | G141: 110761966 | H141: 36 | I141: 10864984 | J141: 0.12
A142: 140 | B142: 106 | C142: San Francisco 49ers | D142: NFL | E142: 2083685 | F142: -0.128 | G142: 110435293 | H142: 37 | I142: 11020516 | J142: 0
A143: 141 | B143: 175 | C143: Norwich | D143: EPL | E143: 2063147 | F143: 0.327 | G143: 51578685 | H143: 151 | I143: 0 | J143: 0
...
